<?xml version="1.0" ?>
<robot name="surg_bot" xmlns:xacro="http://www.ros.org/wiki/xacro">

<xacro:include filename="$(find surg_bot_description)/urdf/materials.xacro" />
<xacro:include filename="$(find surg_bot_description)/urdf/surg_bot.trans" />
<xacro:include filename="$(find surg_bot_description)/urdf/surg_bot.gazebo" />
<link name="base_link">
  <inertial>
    <origin xyz="-0.006200037417416256 -0.004904380492643843 0.04172142536428126" rpy="0 0 0"/>
    <mass value="0.40694896195118685"/>
    <inertia ixx="0.000314" iyy="0.000315" izz="0.000167" ixy="-0.0" iyz="0.0" ixz="0.0"/>
  </inertial>
  <visual>
    <origin xyz="0 0 0" rpy="0 0 0"/>
    <geometry>
      <mesh filename="file://$(find surg_bot_description)/meshes/base_link.stl" scale="0.001 0.001 0.001"/>
    </geometry>
    <material name="silver"/>
  </visual>
  <collision>
    <origin xyz="0 0 0" rpy="0 0 0"/>
    <geometry>
      <mesh filename="file://$(find surg_bot_description)/meshes/base_link.stl" scale="0.001 0.001 0.001"/>
    </geometry>
  </collision>
</link>

<link name="link1_1">
  <inertial>
    <origin xyz="0.1600002369578537 5.540348034358336e-06 -0.017608332454859398" rpy="0 0 0"/>
    <mass value="8.367890341080882"/>
    <inertia ixx="0.012225" iyy="0.118361" izz="0.124365" ixy="-0.0" iyz="-0.0" ixz="-0.001924"/>
  </inertial>
  <visual>
    <origin xyz="0.00617 0.004897 -0.007492" rpy="0 0 0"/>
    <geometry>
      <mesh filename="file://$(find surg_bot_description)/meshes/link1_1.stl" scale="0.001 0.001 0.001"/>
    </geometry>
    <material name="silver"/>
  </visual>
  <collision>
    <origin xyz="0.00617 0.004897 -0.007492" rpy="0 0 0"/>
    <geometry>
      <mesh filename="file://$(find surg_bot_description)/meshes/link1_1.stl" scale="0.001 0.001 0.001"/>
    </geometry>
  </collision>
</link>

<link name="link2_1">
  <inertial>
    <origin xyz="-0.0002220234333368265 -2.5471499862192437e-05 -0.11737370019061386" rpy="0 0 0"/>
    <mass value="3.3490679501648546"/>
    <inertia ixx="0.014417" iyy="0.014057" izz="0.002264" ixy="0.0" iyz="-8e-06" ixz="5.7e-05"/>
  </inertial>
  <visual>
    <origin xyz="-0.31384 0.004907 0.027725" rpy="0 0 0"/>
    <geometry>
      <mesh filename="file://$(find surg_bot_description)/meshes/link2_1.stl" scale="0.001 0.001 0.001"/>
    </geometry>
    <material name="silver"/>
  </visual>
  <collision>
    <origin xyz="-0.31384 0.004907 0.027725" rpy="0 0 0"/>
    <geometry>
      <mesh filename="file://$(find surg_bot_description)/meshes/link2_1.stl" scale="0.001 0.001 0.001"/>
    </geometry>
  </collision>
</link>

<link name="link3_1">
  <inertial>
    <origin xyz="-0.2110414657474451 0.030754237211609886 -2.12340437225067e-06" rpy="0 0 0"/>
    <mass value="4.3450582468708445"/>
    <inertia ixx="0.003399" iyy="0.040399" izz="0.043145" ixy="4.2e-05" iyz="0.0" ixz="-0.0"/>
  </inertial>
  <visual>
    <origin xyz="-0.31383 0.035697 0.232008" rpy="0 0 0"/>
    <geometry>
      <mesh filename="file://$(find surg_bot_description)/meshes/link3_1.stl" scale="0.001 0.001 0.001"/>
    </geometry>
    <material name="silver"/>
  </visual>
  <collision>
    <origin xyz="-0.31383 0.035697 0.232008" rpy="0 0 0"/>
    <geometry>
      <mesh filename="file://$(find surg_bot_description)/meshes/link3_1.stl" scale="0.001 0.001 0.001"/>
    </geometry>
  </collision>
</link>

<link name="link4_1">
  <inertial>
    <origin xyz="-0.029750200264352225 0.049481837853942605 -2.927728003704333e-05" rpy="0 0 0"/>
    <mass value="1.5005041494350506"/>
    <inertia ixx="0.00166" iyy="0.002022" izz="0.002998" ixy="0.000773" iyz="0.0" ixz="-2e-06"/>
  </inertial>
  <visual>
    <origin xyz="0.087684 0.004847 0.232012" rpy="0 0 0"/>
    <geometry>
      <mesh filename="file://$(find surg_bot_description)/meshes/link4_1.stl" scale="0.001 0.001 0.001"/>
    </geometry>
    <material name="silver"/>
  </visual>
  <collision>
    <origin xyz="0.087684 0.004847 0.232012" rpy="0 0 0"/>
    <geometry>
      <mesh filename="file://$(find surg_bot_description)/meshes/link4_1.stl" scale="0.001 0.001 0.001"/>
    </geometry>
  </collision>
</link>

<link name="link5_1">
  <inertial>
    <origin xyz="-3.290383739201763e-05 -0.04081342288708706 0.000588083950290641" rpy="0 0 0"/>
    <mass value="0.38564981413000793"/>
    <inertia ixx="0.000311" iyy="0.000348" izz="0.000552" ixy="-0.0" iyz="1e-06" ixz="-0.0"/>
  </inertial>
  <visual>
    <origin xyz="0.156734 -0.045503 0.232013" rpy="0 0 0"/>
    <geometry>
      <mesh filename="file://$(find surg_bot_description)/meshes/link5_1.stl" scale="0.001 0.001 0.001"/>
    </geometry>
    <material name="silver"/>
  </visual>
  <collision>
    <origin xyz="0.156734 -0.045503 0.232013" rpy="0 0 0"/>
    <geometry>
      <mesh filename="file://$(find surg_bot_description)/meshes/link5_1.stl" scale="0.001 0.001 0.001"/>
    </geometry>
  </collision>
</link>

<link name="end_effector_1">
  <inertial>
    <origin xyz="-4.215304917343232e-07 1.064626750394912e-07 0.0025002918773591454" rpy="0 0 0"/>
    <mass value="0.0010986976730219535"/>
    <inertia ixx="0.0" iyy="0.0" izz="0.0" ixy="-0.0" iyz="0.0" ixz="-0.0"/>
  </inertial>
  <visual>
    <origin xyz="0.156733 -0.002103 0.246763" rpy="0 0 0"/>
    <geometry>
      <mesh filename="file://$(find surg_bot_description)/meshes/end_effector_1.stl" scale="0.001 0.001 0.001"/>
    </geometry>
    <material name="silver"/>
  </visual>
  <collision>
    <origin xyz="0.156733 -0.002103 0.246763" rpy="0 0 0"/>
    <geometry>
      <mesh filename="file://$(find surg_bot_description)/meshes/end_effector_1.stl" scale="0.001 0.001 0.001"/>
    </geometry>
  </collision>
</link>

<joint name="Revolute 1" type="continuous">
  <origin xyz="-0.00617 -0.004897 0.007492" rpy="0 0 0"/>
  <parent link="base_link"/>
  <child link="link1_1"/>
  <axis xyz="0.0 0.0 1.0"/>
</joint>

<joint name="Revolute 2" type="continuous">
  <origin xyz="0.32001 -1e-05 -0.035217" rpy="0 0 0"/>
  <parent link="link1_1"/>
  <child link="link2_1"/>
  <axis xyz="-0.0 0.0 1.0"/>
</joint>

<joint name="Revolute 3" type="revolute">
  <origin xyz="-1e-05 -0.03079 -0.204283" rpy="0 0 0"/>
  <parent link="link2_1"/>
  <child link="link3_1"/>
  <axis xyz="-0.0 -1.0 0.0"/>
  <limit upper="1.570796" lower="-0.174533" effort="100" velocity="100"/>
</joint>

<joint name="Revolute 4" type="revolute">
  <origin xyz="-0.401514 0.03085 -4e-06" rpy="0 0 0"/>
  <parent link="link3_1"/>
  <child link="link4_1"/>
  <axis xyz="-1.0 0.0 -1e-05"/>
  <limit upper="2.268928" lower="-2.268928" effort="100" velocity="100"/>
</joint>

<joint name="Revolute 5" type="revolute">
  <origin xyz="-0.06905 0.05035 -1e-06" rpy="0 0 0"/>
  <parent link="link4_1"/>
  <child link="link5_1"/>
  <axis xyz="-0.0 -1.0 0.0"/>
  <limit upper="2.268928" lower="-2.268928" effort="100" velocity="100"/>
</joint>

<joint name="Rigid 6" type="fixed">
  <origin xyz="1e-06 -0.0434 -0.01475" rpy="0 0 0"/>
  <parent link="link5_1"/>
  <child link="end_effector_1"/>
</joint>

</robot>
