<?xml version="1.0" ?>
<robot name="surg_bot" xmlns:xacro="http://www.ros.org/wiki/xacro">

<xacro:include filename="$(find surg_bot_description)/urdf/materials.xacro" />
<xacro:include filename="$(find surg_bot_description)/urdf/surg_bot.trans" />
<xacro:include filename="$(find surg_bot_description)/urdf/surg_bot.gazebo" />
<link name="base_link">
  <inertial>
    <origin xyz="-0.06278565204512523 -0.018517571033498794 0.006090755429043733" rpy="0 0 0"/>
    <mass value="0.406948961951185"/>
    <inertia ixx="0.000314" iyy="0.000315" izz="0.000167" ixy="-0.0" iyz="0.0" ixz="0.0"/>
  </inertial>
  <visual>
    <origin xyz="0 0 0" rpy="0 0 0"/>
    <geometry>
      <mesh filename="file://$(find surg_bot_description)/meshes/base_link.stl" scale="0.001 0.001 0.001"/>
    </geometry>
    <material name="silver"/>
  </visual>
  <collision>
    <origin xyz="0 0 0" rpy="0 0 0"/>
    <geometry>
      <mesh filename="file://$(find surg_bot_description)/meshes/base_link.stl" scale="0.001 0.001 0.001"/>
    </geometry>
  </collision>
</link>

<link name="link1_1_1">
  <inertial>
    <origin xyz="-0.16001041625629978 -1.5556549154669558e-05 -0.017608002390173735" rpy="0 0 0"/>
    <mass value="8.367890341080868"/>
    <inertia ixx="0.012225" iyy="0.118361" izz="0.124365" ixy="-0.0" iyz="-0.0" ixz="0.001924"/>
  </inertial>
  <visual>
    <origin xyz="0.062755 0.01851 0.028139" rpy="0 0 0"/>
    <geometry>
      <mesh filename="file://$(find surg_bot_description)/meshes/link1_1_1.stl" scale="0.001 0.001 0.001"/>
    </geometry>
    <material name="silver"/>
  </visual>
  <collision>
    <origin xyz="0.062755 0.01851 0.028139" rpy="0 0 0"/>
    <geometry>
      <mesh filename="file://$(find surg_bot_description)/meshes/link1_1_1.stl" scale="0.001 0.001 0.001"/>
    </geometry>
  </collision>
</link>

<link name="link2_1_1">
  <inertial>
    <origin xyz="0.0002218441341833577 2.54552988030593e-05 -0.11737437012585125" rpy="0 0 0"/>
    <mass value="3.3490679501648395"/>
    <inertia ixx="0.014417" iyy="0.014057" izz="0.002264" ixy="0.0" iyz="8e-06" ixz="-5.7e-05"/>
  </inertial>
  <visual>
    <origin xyz="0.382775 0.01851 0.063355" rpy="0 0 0"/>
    <geometry>
      <mesh filename="file://$(find surg_bot_description)/meshes/link2_1_1.stl" scale="0.001 0.001 0.001"/>
    </geometry>
    <material name="silver"/>
  </visual>
  <collision>
    <origin xyz="0.382775 0.01851 0.063355" rpy="0 0 0"/>
    <geometry>
      <mesh filename="file://$(find surg_bot_description)/meshes/link2_1_1.stl" scale="0.001 0.001 0.001"/>
    </geometry>
  </collision>
</link>

<link name="link3_1_1">
  <inertial>
    <origin xyz="0.21104127231910477 0.030645747745601536 -1.8019677435199277e-06" rpy="0 0 0"/>
    <mass value="4.345058247420326"/>
    <inertia ixx="0.003399" iyy="0.040399" izz="0.043145" ixy="4.2e-05" iyz="-0.0" ixz="0.0"/>
  </inertial>
  <visual>
    <origin xyz="0.382765 0.04912 0.267639" rpy="0 0 0"/>
    <geometry>
      <mesh filename="file://$(find surg_bot_description)/meshes/link3_1_1.stl" scale="0.001 0.001 0.001"/>
    </geometry>
    <material name="silver"/>
  </visual>
  <collision>
    <origin xyz="0.382765 0.04912 0.267639" rpy="0 0 0"/>
    <geometry>
      <mesh filename="file://$(find surg_bot_description)/meshes/link3_1_1.stl" scale="0.001 0.001 0.001"/>
    </geometry>
  </collision>
</link>

<link name="link4_1_1">
  <inertial>
    <origin xyz="0.029751892519794897 -0.049482100868121964 -2.921340474681955e-05" rpy="0 0 0"/>
    <mass value="1.5005223483382892"/>
    <inertia ixx="0.00166" iyy="0.002022" izz="0.002999" ixy="0.000773" iyz="-0.0" ixz="2e-06"/>
  </inertial>
  <visual>
    <origin xyz="-0.018748 0.01857 0.267643" rpy="0 0 0"/>
    <geometry>
      <mesh filename="file://$(find surg_bot_description)/meshes/link4_1_1.stl" scale="0.001 0.001 0.001"/>
    </geometry>
    <material name="silver"/>
  </visual>
  <collision>
    <origin xyz="-0.018748 0.01857 0.267643" rpy="0 0 0"/>
    <geometry>
      <mesh filename="file://$(find surg_bot_description)/meshes/link4_1_1.stl" scale="0.001 0.001 0.001"/>
    </geometry>
  </collision>
</link>

<link name="link5_1_1">
  <inertial>
    <origin xyz="3.372453495051331e-05 0.040813406687341375 0.000587414034003364" rpy="0 0 0"/>
    <mass value="0.3856498141159764"/>
    <inertia ixx="0.000311" iyy="0.000348" izz="0.000552" ixy="-0.0" iyz="-1e-06" ixz="0.0"/>
  </inertial>
  <visual>
    <origin xyz="-0.087798 0.06892 0.267643" rpy="0 0 0"/>
    <geometry>
      <mesh filename="file://$(find surg_bot_description)/meshes/link5_1_1.stl" scale="0.001 0.001 0.001"/>
    </geometry>
    <material name="silver"/>
  </visual>
  <collision>
    <origin xyz="-0.087798 0.06892 0.267643" rpy="0 0 0"/>
    <geometry>
      <mesh filename="file://$(find surg_bot_description)/meshes/link5_1_1.stl" scale="0.001 0.001 0.001"/>
    </geometry>
  </collision>
</link>

<link name="end_effector_1_1">
  <inertial>
    <origin xyz="1.4572522974432012e-07 -1.2266364841223565e-07 -0.0025003780571151712" rpy="0 0 0"/>
    <mass value="0.001098697673021953"/>
    <inertia ixx="0.0" iyy="0.0" izz="0.0" ixy="0.0" iyz="0.0" ixz="0.0"/>
  </inertial>
  <visual>
    <origin xyz="-0.087798 0.02552 0.282393" rpy="0 0 0"/>
    <geometry>
      <mesh filename="file://$(find surg_bot_description)/meshes/end_effector_1_1.stl" scale="0.001 0.001 0.001"/>
    </geometry>
    <material name="silver"/>
  </visual>
  <collision>
    <origin xyz="-0.087798 0.02552 0.282393" rpy="0 0 0"/>
    <geometry>
      <mesh filename="file://$(find surg_bot_description)/meshes/end_effector_1_1.stl" scale="0.001 0.001 0.001"/>
    </geometry>
  </collision>
</link>

<joint name="Revolute 7" type="continuous">
  <origin xyz="-0.062755 -0.01851 -0.028139" rpy="0 0 0"/>
  <parent link="base_link"/>
  <child link="link1_1_1"/>
  <axis xyz="-0.0 0.0 1.0"/>
</joint>

<joint name="Revolute 8" type="continuous">
  <origin xyz="-0.32002 0.0 -0.035216" rpy="0 0 0"/>
  <parent link="link1_1_1"/>
  <child link="link2_1_1"/>
  <axis xyz="0.0 0.0 1.0"/>
</joint>

<joint name="Revolute 9" type="revolute">
  <origin xyz="1e-05 -0.03061 -0.204284" rpy="0 0 0"/>
  <parent link="link2_1_1"/>
  <child link="link3_1_1"/>
  <axis xyz="0.0 -1.0 0.0"/>
  <limit upper="0.174533" lower="-1.570796" effort="100" velocity="100"/>
</joint>

<joint name="Revolute 10" type="revolute">
  <origin xyz="0.401513 0.03055 -4e-06" rpy="0 0 0"/>
  <parent link="link3_1_1"/>
  <child link="link4_1_1"/>
  <axis xyz="1.0 -0.0 -1e-05"/>
  <limit upper="2.268928" lower="-2.268928" effort="100" velocity="100"/>
</joint>

<joint name="Revolute 11" type="revolute">
  <origin xyz="0.06905 -0.05035 0.0" rpy="0 0 0"/>
  <parent link="link4_1_1"/>
  <child link="link5_1_1"/>
  <axis xyz="0.0 1.0 0.0"/>
  <limit upper="2.268928" lower="-2.268928" effort="100" velocity="100"/>
</joint>

<joint name="Rigid 12" type="fixed">
  <origin xyz="0.0 0.0434 -0.01475" rpy="0 0 0"/>
  <parent link="link5_1_1"/>
  <child link="end_effector_1_1"/>
</joint>

</robot>
