<?xml version="1.0" encoding="utf-8"?>
<!-- This URDF was automatically created by SolidWorks to URDF Exporter! Originally created by Stephen Brawner (brawner@gmail.com) 
     Commit Version: 1.6.0-4-g7f85cfe  Build Version: 1.6.7995.38578
     For more information, please see http://wiki.ros.org/sw_urdf_exporter -->
<robot
  name="surg_bot_description">
    <link name="dummy_link">
    <inertial>
      <mass value="0"/>
      <origin xyz="0 0 0"/>
      <inertia ixx="0" ixy="0" ixz="0" iyy="0" iyz="0" izz="0"/>
    </inertial>
  </link>

  <link
    name="base_link">
    <inertial>
      <origin
        xyz="0.156154305334649 0.143021834515728 0.0377966098965687"
        rpy="0 0 0" />
      <mass
        value="15.865948579379" />
      <inertia
        ixx="0.425791793185375"
        ixy="-2.49272990063284E-19"
        ixz="8.80947352368975E-19"
        iyy="0.227325591684544"
        iyz="-1.03604978247871E-16"
        izz="0.425791793185375" />
    </inertial>
    <visual>
      <origin
        xyz="0 0 0"
        rpy="0 0 0" />
      <geometry>
        <mesh
          filename="package://surg_bot_description/meshes/Base.STL" />
      </geometry>
      <material
        name="">
        <color
          rgba="0.792156862745098 0.819607843137255 0.933333333333333 1" />
      </material>
    </visual>
    <collision>
      <origin
        xyz="0 0 0"
        rpy="0 0 0" />
      <geometry>
        <mesh
          filename="package://surg_bot_description/meshes/Base.STL" />
      </geometry>
    </collision>
  </link>

    <joint name="dummy_joint" type="fixed">
    <parent link="dummy_link"/>
    <child link="base_link"/>
    <origin xyz="0 0 0"/>
  </joint>

  <link
    name="Link1">
    <inertial>
      <origin
        xyz="0.624338397409122 -0.0571626484779096 0.0377951912740254"
        rpy="0 0 0" />
      <mass
        value="7.06121044359282" />
      <inertia
        ixx="0.114598672993301"
        ixy="0.169939794428495"
        ixz="-7.77193837711208E-07"
        iyy="0.812773240653465"
        iyz="-2.71690833851687E-07"
        izz="0.9034510107497" />
    </inertial>
    <visual>
      <origin
        xyz="0 0 0"
        rpy="0 0 0" />
      <geometry>
        <mesh
          filename="package://surg_bot_description/meshes/Link1.STL" />
      </geometry>
      <material
        name="">
        <color
          rgba="0.792156862745098 0.819607843137255 0.933333333333333 1" />
      </material>
    </visual>
    <collision>
      <origin
        xyz="0 0 0"
        rpy="0 0 0" />
      <geometry>
        <mesh
          filename="package://surg_bot_description/meshes/Link1.STL" />
      </geometry>
    </collision>
  </link>
  <joint
    name="Link1"
    type="revolute">
    <origin
      xyz="0 0 0"
      rpy="0 0 0" />
    <parent
      link="Base" />
    <child
      link="Link1" />
    <axis
      xyz="0 1 0" />
    <limit
      lower="0"
      upper="360"
      effort="10"
      velocity="10" />
    <dynamics
      damping="0.1"
      friction="0.1" />
  </joint>
  <link
    name="Link2">
    <inertial>
      <origin
        xyz="1.01975442465752 -0.49670992636057 0.0381208275285946"
        rpy="0 0 0" />
      <mass
        value="1.13069874193925" />
      <inertia
        ixx="0.00458437296389065"
        ixy="5.32717473916281E-09"
        ixz="3.59275244226836E-09"
        iyy="0.00363844507063892"
        iyz="1.99528034001558E-05"
        izz="0.00545761363628714" />
    </inertial>
    <visual>
      <origin
        xyz="0 0 0"
        rpy="0 0 0" />
      <geometry>
        <mesh
          filename="package://surg_bot_description/meshes/Link2.STL" />
      </geometry>
      <material
        name="">
        <color
          rgba="0.792156862745098 0.819607843137255 0.933333333333333 1" />
      </material>
    </visual>
    <collision>
      <origin
        xyz="0 0 0"
        rpy="0 0 0" />
      <geometry>
        <mesh
          filename="package://surg_bot_description/meshes/Link2.STL" />
      </geometry>
    </collision>
  </link>
  <joint
    name="Link2"
    type="revolute">
    <origin
      xyz="0 0 0"
      rpy="0 0 0" />
    <parent
      link="Link1" />
    <child
      link="Link2" />
    <axis
      xyz="0 -1 0" />
    <limit
      lower="0"
      upper="360"
      effort="10"
      velocity="10" />
    <dynamics
      damping="0.1"
      friction="0.1" />
  </joint>
  <link
    name="Link3">
    <inertial>
      <origin
        xyz="1.01411092169099 -0.503976499916222 -0.0890999138002946"
        rpy="0 0 0" />
      <mass
        value="1.2443873743999" />
      <inertia
        ixx="0.00396574277432574"
        ixy="5.81773357971946E-09"
        ixz="3.60994867141268E-05"
        iyy="0.00491145970466877"
        iyz="5.39750857837317E-09"
        izz="0.00574312393918555" />
    </inertial>
    <visual>
      <origin
        xyz="0 0 0"
        rpy="0 0 0" />
      <geometry>
        <mesh
          filename="package://surg_bot_description/meshes/Link3.STL" />
      </geometry>
      <material
        name="">
        <color
          rgba="0.792156862745098 0.819607843137255 0.933333333333333 1" />
      </material>
    </visual>
    <collision>
      <origin
        xyz="0 0 0"
        rpy="0 0 0" />
      <geometry>
        <mesh
          filename="package://surg_bot_description/meshes/Link3.STL" />
      </geometry>
    </collision>
  </link>
  <joint
    name="Link3"
    type="revolute">
    <origin
      xyz="0 0 0"
      rpy="0 0 0" />
    <parent
      link="Link2" />
    <child
      link="Link3" />
    <axis
      xyz="0 0 1" />
    <limit
      lower="0"
      upper="360"
      effort="10"
      velocity="10" />
    <dynamics
      damping="0.1"
      friction="0.1" />
  </joint>
  <link
    name="Link4">
    <inertial>
      <origin
        xyz="0.511754305334647 -0.503976330156753 -0.0892033901034228"
        rpy="0 0 0" />
      <mass
        value="4.09760403890471" />
      <inertia
        ixx="0.00720650890476304"
        ixy="-1.94838850227079E-34"
        ixz="8.2378044393481E-16"
        iyy="0.24441466048146"
        iyz="3.67653427438345E-35"
        izz="0.24441466048146" />
    </inertial>
    <visual>
      <origin
        xyz="0 0 0"
        rpy="0 0 0" />
      <geometry>
        <mesh
          filename="package://surg_bot_description/meshes/Link4.STL" />
      </geometry>
      <material
        name="">
        <color
          rgba="0.792156862745098 0.819607843137255 0.933333333333333 1" />
      </material>
    </visual>
    <collision>
      <origin
        xyz="0 0 0"
        rpy="0 0 0" />
      <geometry>
        <mesh
          filename="package://surg_bot_description/meshes/Link4.STL" />
      </geometry>
    </collision>
  </link>
  <joint
    name="Link4"
    type="revolute">
    <origin
      xyz="0 0 0"
      rpy="0 0 0" />
    <parent
      link="Link3" />
    <child
      link="Link4" />
    <axis
      xyz="0 0 1" />
    <limit
      lower="0"
      upper="360"
      effort="10"
      velocity="10" />
    <dynamics
      damping="0.1"
      friction="0.1" />
  </joint>
  <link
    name="Link5">
    <inertial>
      <origin
        xyz="0.0824669966713169 -0.503976328534475 -0.0851379243188525"
        rpy="0 0 0" />
      <mass
        value="0.283181051897044" />
      <inertia
        ixx="0.000568886076164115"
        ixy="-1.64530557728285E-11"
        ixz="2.22006843974026E-05"
        iyy="0.000507831779081121"
        iyz="-3.26763363103908E-11"
        izz="0.000442919551088538" />
    </inertial>
    <visual>
      <origin
        xyz="0 0 0"
        rpy="0 0 0" />
      <geometry>
        <mesh
          filename="package://surg_bot_description/meshes/Link5.STL" />
      </geometry>
      <material
        name="">
        <color
          rgba="0.792156862745098 0.819607843137255 0.933333333333333 1" />
      </material>
    </visual>
    <collision>
      <origin
        xyz="0 0 0"
        rpy="0 0 0" />
      <geometry>
        <mesh
          filename="package://surg_bot_description/meshes/Link5.STL" />
      </geometry>
    </collision>
  </link>
  <joint
    name="Link5"
    type="revolute">
    <origin
      xyz="0 0 0"
      rpy="0 0 0" />
    <parent
      link="Link4" />
    <child
      link="Link5" />
    <axis
      xyz="-1 0 0" />
    <limit
      lower="0"
      upper="360"
      effort="10"
      velocity="10" />
    <dynamics
      damping="0.1"
      friction="0.1" />
  </joint>
  <link
    name="Link6">
    <inertial>
      <origin
        xyz="-0.0276188536498135 -0.503976330156753 0.142186450912115"
        rpy="0 0 0" />
      <mass
        value="0.467880622236969" />
      <inertia
        ixx="0.00309574826083503"
        ixy="-1.57264015968036E-19"
        ixz="0.00273231903124134"
        iyy="0.00610919382537965"
        iyz="-1.1680228158703E-20"
        izz="0.00309574826083491" />
    </inertial>
    <visual>
      <origin
        xyz="0 0 0"
        rpy="0 0 0" />
      <geometry>
        <mesh
          filename="package://surg_bot_description/meshes/Link6.STL" />
      </geometry>
      <material
        name="">
        <color
          rgba="0.792156862745098 0.819607843137255 0.933333333333333 1" />
      </material>
    </visual>
    <collision>
      <origin
        xyz="0 0 0"
        rpy="0 0 0" />
      <geometry>
        <mesh
          filename="package://surg_bot_description/meshes/Link6.STL" />
      </geometry>
    </collision>
  </link>
  <joint
    name="Link6"
    type="revolute">
    <origin
      xyz="0 0 0"
      rpy="0 0 0" />
    <parent
      link="Link5" />
    <child
      link="Link6" />
    <axis
      xyz="-1 0 0" />
    <limit
      lower="0"
      upper="360"
      effort="10"
      velocity="10" />
    <dynamics
      damping="0.1"
      friction="0.1" />
  </joint>
  <link
    name="Link7">
    <inertial>
      <origin
        xyz="-0.300392308386059 -0.503976329371158 0.228847533076155"
        rpy="0 0 0" />
      <mass
        value="1.16594380268497" />
      <inertia
        ixx="0.003018457640304"
        ixy="4.43193966344834E-10"
        ixz="-1.1617058957329E-05"
        iyy="0.0032146719752099"
        iyz="5.55606583079323E-11"
        izz="0.00561915891659141" />
    </inertial>
    <visual>
      <origin
        xyz="0 0 0"
        rpy="0 0 0" />
      <geometry>
        <mesh
          filename="package://surg_bot_description/meshes/Link7.STL" />
      </geometry>
      <material
        name="">
        <color
          rgba="0.792156862745098 0.819607843137255 0.933333333333333 1" />
      </material>
    </visual>
    <collision>
      <origin
        xyz="0 0 0"
        rpy="0 0 0" />
      <geometry>
        <mesh
          filename="package://surg_bot_description/meshes/Link7.STL" />
      </geometry>
    </collision>
  </link>
  <joint
    name="Link7"
    type="revolute">
    <origin
      xyz="0 0 0"
      rpy="0 0 0" />
    <parent
      link="Link6" />
    <child
      link="Link7" />
    <axis
      xyz="-1 0 0" />
    <limit
      lower="0"
      upper="360"
      effort="10"
      velocity="10" />
    <dynamics
      damping="0.1"
      friction="0.1" />
  </joint>
  <link
    name="Link8">
    <inertial>
      <origin
        xyz="-0.0300875480220664 -0.328546869994388 -0.0334671424337518"
        rpy="0 0 0" />
      <mass
        value="75.3932063564624" />
      <inertia
        ixx="7.65834389642953"
        ixy="-3.86969736153903"
        ixz="-0.829461612105236"
        iyy="14.3620627235996"
        iyz="-0.965586516879635"
        izz="19.2027030975942" />
    </inertial>
    <visual>
      <origin
        xyz="0 0 0"
        rpy="0 0 0" />
      <geometry>
        <mesh
          filename="package://surg_bot_description/meshes/Link8.STL" />
      </geometry>
      <material
        name="">
        <color
          rgba="0.792156862745098 0.819607843137255 0.933333333333333 1" />
      </material>
    </visual>
    <collision>
      <origin
        xyz="0 0 0"
        rpy="0 0 0" />
      <geometry>
        <mesh
          filename="package://surg_bot_description/meshes/Link8.STL" />
      </geometry>
    </collision>
  </link>
  <joint
    name="Link8"
    type="revolute">
    <origin
      xyz="0 0 0"
      rpy="0 0 0" />
    <parent
      link="Link7" />
    <child
      link="Link8" />
    <axis
      xyz="0 0 -1" />
    <limit
      lower="0"
      upper="360"
      effort="10"
      velocity="10" />
    <dynamics
      damping="0.1"
      friction="0.1" />
  </joint>
</robot>