<?xml version="1.0" ?>
<robot name="surg_bot" xmlns:xacro="http://www.ros.org/wiki/xacro">

<xacro:include filename="$(find surg_bot_description)/urdf/materials.xacro" />
<xacro:include filename="$(find surg_bot_description)/urdf/surg_bot.trans" />
<xacro:include filename="$(find surg_bot_description)/urdf/surg_bot.gazebo" />
<link name="base_link">
  <inertial>
    <origin xyz="-4.031295976229773e-05 2.551630137478745e-06 -0.02955399218078996" rpy="0 0 0"/>
    <mass value="0.4069489619511855"/>
    <inertia ixx="0.000314" iyy="0.000315" izz="0.000167" ixy="-0.0" iyz="0.0" ixz="0.0"/>
  </inertial>
  <visual>
    <origin xyz="0 0 0" rpy="0 0 0"/>
    <geometry>
      <mesh filename="file://$(find surg_bot_description)/meshes/base_link.stl" scale="0.001 0.001 0.001"/>
    </geometry>
    <material name="silver"/>
  </visual>
  <collision>
    <origin xyz="0 0 0" rpy="0 0 0"/>
    <geometry>
      <mesh filename="file://$(find surg_bot_description)/meshes/base_link.stl" scale="0.001 0.001 0.001"/>
    </geometry>
  </collision>
</link>

<link name="link1_1_1">
  <inertial>
    <origin xyz="-0.16001007717101118 -1.5433885539871676e-05 -0.01760775000004905" rpy="0 0 0"/>
    <mass value="8.367890341080868"/>
    <inertia ixx="0.012225" iyy="0.118361" izz="0.124365" ixy="0.0" iyz="0.0" ixz="0.001924"/>
  </inertial>
  <visual>
    <origin xyz="1e-05 -1e-05 0.063784" rpy="0 0 0"/>
    <geometry>
      <mesh filename="file://$(find surg_bot_description)/meshes/link1_1_1.stl" scale="0.001 0.001 0.001"/>
    </geometry>
    <material name="silver"/>
  </visual>
  <collision>
    <origin xyz="1e-05 -1e-05 0.063784" rpy="0 0 0"/>
    <geometry>
      <mesh filename="file://$(find surg_bot_description)/meshes/link1_1_1.stl" scale="0.001 0.001 0.001"/>
    </geometry>
  </collision>
</link>

<link name="link2_1_1">
  <inertial>
    <origin xyz="0.00022218321954753373 2.5577962440391797e-05 -0.11737411773568335" rpy="0 0 0"/>
    <mass value="3.3490679501648595"/>
    <inertia ixx="0.014417" iyy="0.014057" izz="0.002264" ixy="0.0" iyz="8e-06" ixz="-5.7e-05"/>
  </inertial>
  <visual>
    <origin xyz="0.32003 -1e-05 0.099" rpy="0 0 0"/>
    <geometry>
      <mesh filename="file://$(find surg_bot_description)/meshes/link2_1_1.stl" scale="0.001 0.001 0.001"/>
    </geometry>
    <material name="silver"/>
  </visual>
  <collision>
    <origin xyz="0.32003 -1e-05 0.099" rpy="0 0 0"/>
    <geometry>
      <mesh filename="file://$(find surg_bot_description)/meshes/link2_1_1.stl" scale="0.001 0.001 0.001"/>
    </geometry>
  </collision>
</link>

<link name="link3_1_1">
  <inertial>
    <origin xyz="0.2110416079169363 -0.03064586937985538 1.5515587032943756e-06" rpy="0 0 0"/>
    <mass value="4.345058247420323"/>
    <inertia ixx="0.003399" iyy="0.040399" izz="0.043145" ixy="-4.2e-05" iyz="0.0" ixz="-0.0"/>
  </inertial>
  <visual>
    <origin xyz="0.32002 -0.0308 0.303283" rpy="0 0 0"/>
    <geometry>
      <mesh filename="file://$(find surg_bot_description)/meshes/link3_1_1.stl" scale="0.001 0.001 0.001"/>
    </geometry>
    <material name="silver"/>
  </visual>
  <collision>
    <origin xyz="0.32002 -0.0308 0.303283" rpy="0 0 0"/>
    <geometry>
      <mesh filename="file://$(find surg_bot_description)/meshes/link3_1_1.stl" scale="0.001 0.001 0.001"/>
    </geometry>
  </collision>
</link>

<link name="link4_1_1">
  <inertial>
    <origin xyz="0.027751206627339403 -0.049481985744040745 -2.8670883511938694e-05" rpy="0 0 0"/>
    <mass value="1.50052234833829"/>
    <inertia ixx="0.00166" iyy="0.002022" izz="0.002999" ixy="0.000773" iyz="-0.0" ixz="2e-06"/>
  </inertial>
  <visual>
    <origin xyz="-0.081494 -0.00025 0.30328" rpy="0 0 0"/>
    <geometry>
      <mesh filename="file://$(find surg_bot_description)/meshes/link4_1_1.stl" scale="0.001 0.001 0.001"/>
    </geometry>
    <material name="silver"/>
  </visual>
  <collision>
    <origin xyz="-0.081494 -0.00025 0.30328" rpy="0 0 0"/>
    <geometry>
      <mesh filename="file://$(find surg_bot_description)/meshes/link4_1_1.stl" scale="0.001 0.001 0.001"/>
    </geometry>
  </collision>
</link>

<link name="link5_1_1">
  <inertial>
    <origin xyz="3.305227672389943e-05 0.04081352935092518 0.0005877302186016453" rpy="0 0 0"/>
    <mass value="0.3856498141159767"/>
    <inertia ixx="0.000311" iyy="0.000348" izz="0.000552" ixy="-0.0" iyz="-1e-06" ixz="0.0"/>
  </inertial>
  <visual>
    <origin xyz="-0.148544 0.0501 0.303279" rpy="0 0 0"/>
    <geometry>
      <mesh filename="file://$(find surg_bot_description)/meshes/link5_1_1.stl" scale="0.001 0.001 0.001"/>
    </geometry>
    <material name="silver"/>
  </visual>
  <collision>
    <origin xyz="-0.148544 0.0501 0.303279" rpy="0 0 0"/>
    <geometry>
      <mesh filename="file://$(find surg_bot_description)/meshes/link5_1_1.stl" scale="0.001 0.001 0.001"/>
    </geometry>
  </collision>
</link>

<link name="end_effector_1_1">
  <inertial>
    <origin xyz="-1.822417527441722e-07 6.200430793801281e-13 -0.002500062517189483" rpy="0 0 0"/>
    <mass value="0.001098697673021953"/>
    <inertia ixx="0.0" iyy="0.0" izz="0.0" ixy="-0.0" iyz="-0.0" ixz="-0.0"/>
  </inertial>
  <visual>
    <origin xyz="-0.148544 0.0067 0.318029" rpy="0 0 0"/>
    <geometry>
      <mesh filename="file://$(find surg_bot_description)/meshes/end_effector_1_1.stl" scale="0.001 0.001 0.001"/>
    </geometry>
    <material name="silver"/>
  </visual>
  <collision>
    <origin xyz="-0.148544 0.0067 0.318029" rpy="0 0 0"/>
    <geometry>
      <mesh filename="file://$(find surg_bot_description)/meshes/end_effector_1_1.stl" scale="0.001 0.001 0.001"/>
    </geometry>
  </collision>
</link>

<joint name="revolute_1" type="continuous">
  <origin xyz="-1e-05 1e-05 -0.063784" rpy="0 0 0"/>
  <parent link="base_link"/>
  <child link="link1_1_1"/>
  <axis xyz="0.0 0.0 1.0"/>
</joint>

<joint name="revolute_2" type="continuous">
  <origin xyz="-0.32002 0.0 -0.035216" rpy="0 0 0"/>
  <parent link="link1_1_1"/>
  <child link="link2_1_1"/>
  <axis xyz="0.0 0.0 1.0"/>
</joint>

<joint name="revolute_3" type="revolute">
  <origin xyz="1e-05 0.03079 -0.204283" rpy="0 0 0"/>
  <parent link="link2_1_1"/>
  <child link="link3_1_1"/>
  <axis xyz="0.0 1.0 -0.0"/>
  <limit upper="1.570796" lower="-0.174533" effort="100" velocity="100"/>
</joint>

<joint name="revolute_4" type="revolute">
  <origin xyz="0.401514 -0.03055 3e-06" rpy="0 0 0"/>
  <parent link="link3_1_1"/>
  <child link="link4_1_1"/>
  <axis xyz="1.0 0.0 1e-05"/>
  <limit upper="2.268928" lower="-2.268928" effort="100" velocity="100"/>
</joint>

<joint name="revolute_5" type="revolute">
  <origin xyz="0.06705 -0.05035 1e-06" rpy="0 0 0"/>
  <parent link="link4_1_1"/>
  <child link="link5_1_1"/>
  <axis xyz="0.0 1.0 0.0"/>
  <limit upper="2.268928" lower="-2.268928" effort="100" velocity="100"/>
</joint>

<joint name="rigid_1" type="fixed">
  <origin xyz="0.0 0.0434 -0.01475" rpy="0 0 0"/>
  <parent link="link5_1_1"/>
  <child link="end_effector_1_1"/>
</joint>

</robot>
