<?xml version="1.0" ?>
<robot name="surg_bot" xmlns:xacro="http://www.ros.org/wiki/xacro">

<xacro:include filename="$(find surg_bot_description)/urdf/materials.xacro" />
<xacro:include filename="$(find surg_bot_description)/urdf/surg_bot.trans" />
<xacro:include filename="$(find surg_bot_description)/urdf/surg_bot.gazebo" />
<link name="base_link">
  <inertial>
    <origin xyz="-4.031295976229773e-05 2.551630137478745e-06 -0.02955399218078996" rpy="0 0 0"/>
    <mass value="0.4069489619511855"/>
    <inertia ixx="0.000314" iyy="0.000315" izz="0.000167" ixy="-0.0" iyz="0.0" ixz="0.0"/>
  </inertial>
  <visual>
    <origin xyz="0 0 0" rpy="0 0 0"/>
    <geometry>
      <mesh filename="file://$(find surg_bot_description)/meshes/base_link.stl" scale="0.001 0.001 0.001"/>
    </geometry>
    <material name="silver"/>
  </visual>
  <collision>
    <origin xyz="0 0 0" rpy="0 0 0"/>
    <geometry>
      <mesh filename="file://$(find surg_bot_description)/meshes/base_link.stl" scale="0.001 0.001 0.001"/>
    </geometry>
  </collision>
</link>

<link name="link1_1_1">
  <inertial>
    <origin xyz="-0.16000855446108672 0.0006982755267684382 -0.017607750000049494" rpy="0 0 0"/>
    <mass value="8.367890341080868"/>
    <inertia ixx="0.012227" iyy="0.118359" izz="0.124365" ixy="0.000473" iyz="-9e-06" ixz="0.001924"/>
  </inertial>
  <visual>
    <origin xyz="1e-05 -1e-05 0.063784" rpy="0 0 0"/>
    <geometry>
      <mesh filename="file://$(find surg_bot_description)/meshes/link1_1_1.stl" scale="0.001 0.001 0.001"/>
    </geometry>
    <material name="silver"/>
  </visual>
  <collision>
    <origin xyz="1e-05 -1e-05 0.063784" rpy="0 0 0"/>
    <geometry>
      <mesh filename="file://$(find surg_bot_description)/meshes/link1_1_1.stl" scale="0.001 0.001 0.001"/>
    </geometry>
  </collision>
</link>

<link name="link2_1_1">
  <inertial>
    <origin xyz="0.0002224902754690561 2.4896581295632018e-05 -0.1173741177356834" rpy="0 0 0"/>
    <mass value="3.3490679501648595"/>
    <inertia ixx="0.014417" iyy="0.014057" izz="0.002264" ixy="-2e-06" iyz="8e-06" ixz="-5.7e-05"/>
  </inertial>
  <visual>
    <origin xyz="0.320027 -0.001437 0.099" rpy="0 0 0"/>
    <geometry>
      <mesh filename="file://$(find surg_bot_description)/meshes/link2_1_1.stl" scale="0.001 0.001 0.001"/>
    </geometry>
    <material name="silver"/>
  </visual>
  <collision>
    <origin xyz="0.320027 -0.001437 0.099" rpy="0 0 0"/>
    <geometry>
      <mesh filename="file://$(find surg_bot_description)/meshes/link2_1_1.stl" scale="0.001 0.001 0.001"/>
    </geometry>
  </collision>
</link>

<link name="link3_1">
  <inertial>
    <origin xyz="0.13549556866217186 0.030032525454134127 -4.999999703714231e-07" rpy="0 0 0"/>
    <mass value="1.7602626049739658"/>
    <inertia ixx="0.001766" iyy="0.008244" izz="0.009744" ixy="3.2e-05" iyz="0.0" ixz="0.0"/>
  </inertial>
  <visual>
    <origin xyz="0.320168 0.029172 0.303283" rpy="0 0 0"/>
    <geometry>
      <mesh filename="file://$(find surg_bot_description)/meshes/link3_1.stl" scale="0.001 0.001 0.001"/>
    </geometry>
    <material name="silver"/>
  </visual>
  <collision>
    <origin xyz="0.320168 0.029172 0.303283" rpy="0 0 0"/>
    <geometry>
      <mesh filename="file://$(find surg_bot_description)/meshes/link3_1.stl" scale="0.001 0.001 0.001"/>
    </geometry>
  </collision>
</link>

<link name="link4_1">
  <inertial>
    <origin xyz="0.02600502860609198 -0.04510246183047751 -5.119758128557805e-07" rpy="0 0 0"/>
    <mass value="1.4039319321687402"/>
    <inertia ixx="0.00142" iyy="0.001886" izz="0.002652" ixy="0.000674" iyz="0.0" ixz="-0.0"/>
  </inertial>
  <visual>
    <origin xyz="0.065316 -0.000267 0.303283" rpy="0 0 0"/>
    <geometry>
      <mesh filename="file://$(find surg_bot_description)/meshes/link4_1.stl" scale="0.001 0.001 0.001"/>
    </geometry>
    <material name="silver"/>
  </visual>
  <collision>
    <origin xyz="0.065316 -0.000267 0.303283" rpy="0 0 0"/>
    <geometry>
      <mesh filename="file://$(find surg_bot_description)/meshes/link4_1.stl" scale="0.001 0.001 0.001"/>
    </geometry>
  </collision>
</link>

<link name="link5_1_1">
  <inertial>
    <origin xyz="0.0002259892794144409 0.03886333123442502 0.0005887467592404771" rpy="0 0 0"/>
    <mass value="0.38469776659589416"/>
    <inertia ixx="0.000309" iyy="0.000348" izz="0.00055" ixy="0.0" iyz="-1e-06" ixz="0.0"/>
  </inertial>
  <visual>
    <origin xyz="0.000274 0.041925 0.303283" rpy="0 0 0"/>
    <geometry>
      <mesh filename="file://$(find surg_bot_description)/meshes/link5_1_1.stl" scale="0.001 0.001 0.001"/>
    </geometry>
    <material name="silver"/>
  </visual>
  <collision>
    <origin xyz="0.000274 0.041925 0.303283" rpy="0 0 0"/>
    <geometry>
      <mesh filename="file://$(find surg_bot_description)/meshes/link5_1_1.stl" scale="0.001 0.001 0.001"/>
    </geometry>
  </collision>
</link>

<link name="end_effector_1_1">
  <inertial>
    <origin xyz="-2.7668857425572823e-07 -2.5305395503594057e-07 0.002499500002298649" rpy="0 0 0"/>
    <mass value="0.001098697673021953"/>
    <inertia ixx="0.0" iyy="0.0" izz="0.0" ixy="-0.0" iyz="-0.0" ixz="0.0"/>
  </inertial>
  <visual>
    <origin xyz="6.9e-05 0.000575 0.318033" rpy="0 0 0"/>
    <geometry>
      <mesh filename="file://$(find surg_bot_description)/meshes/end_effector_1_1.stl" scale="0.001 0.001 0.001"/>
    </geometry>
    <material name="silver"/>
  </visual>
  <collision>
    <origin xyz="6.9e-05 0.000575 0.318033" rpy="0 0 0"/>
    <geometry>
      <mesh filename="file://$(find surg_bot_description)/meshes/end_effector_1_1.stl" scale="0.001 0.001 0.001"/>
    </geometry>
  </collision>
</link>

<joint name="joint0" type="continuous">
  <origin xyz="-1e-05 1e-05 -0.063784" rpy="0 0 0"/>
  <parent link="base_link"/>
  <child link="link1_1_1"/>
  <axis xyz="0.0 0.0 1.0"/>
</joint>

<joint name="joint1" type="continuous">
  <origin xyz="-0.320017 0.001427 -0.035216" rpy="0 0 0"/>
  <parent link="link1_1_1"/>
  <child link="link2_1_1"/>
  <axis xyz="0.0 0.0 1.0"/>
</joint>

<joint name="joint2" type="revolute">
  <origin xyz="-0.000141 -0.030609 -0.204283" rpy="0 0 0"/>
  <parent link="link2_1_1"/>
  <child link="link3_1"/>
  <axis xyz="-0.004946 -0.999988 0.0"/>
  <limit upper="0.174533" lower="-1.570796" effort="100" velocity="100"/>
</joint>

<joint name="joint3" type="revolute">
  <origin xyz="0.254852 0.029439 0.0" rpy="0 0 0"/>
  <parent link="link3_1"/>
  <child link="link4_1"/>
  <axis xyz="0.999988 -0.004946 0.0"/>
  <limit upper="2.268928" lower="-2.268928" effort="100" velocity="100"/>
</joint>

<joint name="joint4" type="continuous">
  <origin xyz="0.065042 -0.042192 0.0" rpy="0 0 0"/>
  <parent link="link4_1"/>
  <child link="link5_1_1"/>
  <axis xyz="0.004946 0.999988 -0.0"/>
</joint>

<joint name="rigid1" type="fixed">
  <origin xyz="0.000205 0.04135 -0.01475" rpy="0 0 0"/>
  <parent link="link5_1_1"/>
  <child link="end_effector_1_1"/>
</joint>

</robot>
