<?xml version="1.0" encoding="utf-8"?>

<!-- This URDF was automatically created by SolidWorks to URDF Exporter! Originally created by Stephen Brawner (brawner@gmail.com) 
     Commit Version: 1.6.0-4-g7f85cfe  Build Version: 1.6.7995.38578
     For more information, please see http://wiki.ros.org/sw_urdf_exporter -->
<robot
  name="surg_bot_description">
  <link name="ceiling">
    <visual>
      <geometry>
        <box size="1 1 0.1"/>
      </geometry>
    </visual>
  </link>

 <joint name="ceiling_joint" type="fixed">
  <origin
  xyz="0 0 -0.37"
  rpy="0 0 0" />
    <parent link="ceiling"/>
    <child link="base_link"/>
    <gazebo>
      <plugin name="gazebo_ros_control" filename="libgazebo_ros_control.so"/>
      <robotNamespace>/my_robot</robotNamespace>
    </gazebo>
  </joint>
  
  <link
    name="base_link">
    <inertial>
      <origin
        xyz="0 0 0"
        rpy="0 0 0" />
      <mass
        value="15.865948579379" />
      <inertia
        ixx="0.425791793185375"
        ixy="-2.50159888909237E-19"
        ixz="8.80947352368975E-19"
        iyy="0.227325591684544"
        iyz="-1.0360921171599E-16"
        izz="0.425791793185375" />
    </inertial>
    <visual>
      <origin
        xyz="0 0 0"
        rpy="0 0 0" />
      <geometry>
        <mesh
          filename="/home/alec/Autotracking_Surgical_Lamp/ros2_ws/src/surg_bot/surg_bot_description/meshes/base_link.STL" />
      </geometry>
      <material
        name="">
        <color
          rgba="0 0.5 0.5 1" />
      </material>
    </visual>
    <collision>
      <origin
        xyz="0 0 0"
        rpy="0 0 0" />
      <geometry>
        <mesh
          filename="/home/alec/Autotracking_Surgical_Lamp/ros2_ws/src/surg_bot/surg_bot_description/meshes/base_link.STL" />
      </geometry>
    </collision>
  </link>
  <link
    name="Link1">
    <inertial>
      <origin
        xyz="0.46818 -0.054545 -1.4186E-06"
        rpy="0 0 0" />
      <mass
        value="7.0612" />
      <inertia
        ixx="0.1146"
        ixy="0.16994"
        ixz="-7.7719E-07"
        iyy="0.81277"
        iyz="-2.7169E-07"
        izz="0.90345" />
    </inertial>
    <visual>
      <origin
        xyz="0 0 0"
        rpy="0 0 0" />
      <geometry>
        <mesh
          filename="/home/alec/Autotracking_Surgical_Lamp/ros2_ws/src/surg_bot/surg_bot_description/meshes/Link1.STL" />
      </geometry>
      <material
        name="">
        <color
          rgba="0 0.5 0.5 1" />
      </material>
    </visual>
    <collision>
      <origin
        xyz="0 0 0"
        rpy="0 0 0" />
      <geometry>
        <mesh
          filename="/home/alec/Autotracking_Surgical_Lamp/ros2_ws/src/surg_bot/surg_bot_description/meshes/Link1.STL" />
      </geometry>
    </collision>
  </link>
  <joint
    name="Joint0"
    type="continuous">
    <origin
      xyz="0 0 0"
      rpy="1.5708 0 0" />
    <parent
      link="base_link" />
    <child
      link="Link1" />
    <axis
      xyz="0 1 0" />
    <limit
      lower="0"
      upper="0"
      effort="0"
      velocity="0" />
  </joint>
  <link
    name="Link2">
    <inertial>
      <origin
        xyz="0.00032422 0.11973 1.1932E-07"
        rpy="0 0 0" />
      <mass
        value="1.1307" />
      <inertia
        ixx="0.0054576"
        ixy="-1.9953E-05"
        ixz="3.5928E-09"
        iyy="0.0036384"
        iyz="-5.3272E-09"
        izz="0.0045844" />
    </inertial>
    <visual>
      <origin
        xyz="0 0 0"
        rpy="0 0 0" />
      <geometry>
        <mesh
          filename="/home/alec/Autotracking_Surgical_Lamp/ros2_ws/src/surg_bot/surg_bot_description/meshes/Link2.STL" />
      </geometry>
      <material
        name="">
        <color
          rgba="0 0.5 0.5 1" />
      </material>
    </visual>
    <collision>
      <origin
        xyz="0 0 0"
        rpy="0 0 0" />
      <geometry>
        <mesh
          filename="/home/alec/Autotracking_Surgical_Lamp/ros2_ws/src/surg_bot/surg_bot_description/meshes/Link2.STL" />
      </geometry>
    </collision>
  </link>
  <joint
    name="Joint1"
    type="continuous">
    <origin
      xyz="0.8636 -0.37436 0"
      rpy="0 -1.5708 0" />
    <parent
      link="Link1" />
    <child
      link="Link2" />
    <axis
      xyz="0 1 0" />
    <limit
      lower="0"
      upper="0"
      effort="0"
      velocity="0" />
  </joint>
  <link
    name="Link3">
    <inertial>
      <origin
        xyz="-0.076097 1.6976E-07 -0.0056434"
        rpy="0 0 0" />
      <mass
        value="1.2444" />
      <inertia
        ixx="0.0057431"
        ixy="-5.3975E-09"
        ixz="3.6099E-05"
        iyy="0.0049115"
        iyz="-5.8177E-09"
        izz="0.0039657" />
    </inertial>
    <visual>
      <origin
        xyz="0 0 0"
        rpy="0 0 0" />
      <geometry>
        <mesh
          filename="/home/alec/Autotracking_Surgical_Lamp/ros2_ws/src/surg_bot/surg_bot_description/meshes/Link3.STL" />
      </geometry>
      <material
        name="">
        <color
          rgba="0 0.5 0.5 1" />
      </material>
    </visual>
    <collision>
      <origin
        xyz="0 0 0"
        rpy="0 0 0" />
      <geometry>
        <mesh
          filename="/home/alec/Autotracking_Surgical_Lamp/ros2_ws/src/surg_bot/surg_bot_description/meshes/Link3.STL" />
      </geometry>
    </collision>
  </link>
  <joint
    name="Joint2"
    type="continuous">
    <origin
      xyz="-0.0508 1.6976E-07 0"
      rpy="0 0 0" />
    <parent
      link="Link2" />
    <child
      link="Link3" />
    <axis
      xyz="1 0 0" />
  </joint>
  <link
    name="Link4">
    <inertial>
      <origin
        xyz="-8.063E-15 -1.1102E-16 -0.4572"
        rpy="0 0 0" />
      <mass
        value="4.0976" />
      <inertia
        ixx="0.24441"
        ixy="-3.6765E-35"
        ixz="-8.2378E-16"
        iyy="0.24441"
        iyz="-1.9484E-34"
        izz="0.0072065" />
    </inertial>
    <visual>
      <origin
        xyz="0 0 0"
        rpy="0 0 0" />
      <geometry>
        <mesh
          filename="/home/alec/Autotracking_Surgical_Lamp/ros2_ws/src/surg_bot/surg_bot_description/meshes/Link4.STL" />
      </geometry>
      <material
        name="">
        <color
          rgba="0 0.5 0.5 1" />
      </material>
    </visual>
    <collision>
      <origin
        xyz="0 0 0"
        rpy="0 0 0" />
      <geometry>
        <mesh
          filename="/home/alec/Autotracking_Surgical_Lamp/ros2_ws/src/surg_bot/surg_bot_description/meshes/Link4.STL" />
      </geometry>
    </collision>
  </link>
  <joint
    name="Joint3"
    type="fixed">
    <origin
      xyz="-0.0762 0 -0.0508"
      rpy="0 0 3.1416" />
    <parent
      link="Link3" />
    <child
      link="Link4" />
    <axis
      xyz="0 0 1" />
  </joint>
  <link
    name="Link5">
    <inertial>
      <origin
        xyz="0.0040655 -1.6223E-09 -0.048287"
        rpy="0 0 0" />
      <mass
        value="0.28318" />
      <inertia
        ixx="0.00044292"
        ixy="3.2676E-11"
        ixz="2.2201E-05"
        iyy="0.00050783"
        iyz="1.6453E-11"
        izz="0.00056889" />
    </inertial>
    <visual>
      <origin
        xyz="0 0 0"
        rpy="0 0 0" />
      <geometry>
        <mesh
          filename="/home/alec/Autotracking_Surgical_Lamp/ros2_ws/src/surg_bot/surg_bot_description/meshes/Link5.STL" />
      </geometry>
      <material
        name="">
        <color
          rgba="0 0.5 0.5 1" />
      </material>
    </visual>
    <collision>
      <origin
        xyz="0 0 0"
        rpy="0 0 0" />
      <geometry>
        <mesh
          filename="/home/alec/Autotracking_Surgical_Lamp/ros2_ws/src/surg_bot/surg_bot_description/meshes/Link5.STL" />
      </geometry>
    </collision>
  </link>
  <joint
    name="Joint4"
    type="fixed">
    <origin
      xyz="0 0 -0.8382"
      rpy="0 0 3.1416" />
    <parent
      link="Link4" />
    <child
      link="Link5" />
    <axis
      xyz="0 0 1" />
    <limit
      lower="0"
      upper="0"
      effort="0"
      velocity="0" />
  </joint>
  <link
    name="Link6">
    <inertial>
      <origin
        xyz="0.23139 -0.01 -0.15837"
        rpy="0 0 0" />
      <mass
        value="0.46788" />
      <inertia
        ixx="0.0030957"
        ixy="-4.6541E-19"
        ixz="0.0027323"
        iyy="0.0061092"
        iyz="6.769E-19"
        izz="0.0030957" />
    </inertial>
    <visual>
      <origin
        xyz="0 0 0"
        rpy="0 0 0" />
      <geometry>
        <mesh
          filename="/home/alec/Autotracking_Surgical_Lamp/ros2_ws/src/surg_bot/surg_bot_description/meshes/Link6.STL" />
      </geometry>
      <material
        name="">
        <color
          rgba="0 0.5 0.5 1" />
      </material>
    </visual>
    <collision>
      <origin
        xyz="0 0 0"
        rpy="0 0 0" />
      <geometry>
        <mesh
          filename="/home/alec/Autotracking_Surgical_Lamp/ros2_ws/src/surg_bot/surg_bot_description/meshes/Link6.STL" />
      </geometry>
    </collision>
  </link>
  <joint
    name="Joint5"
    type="continuous">
    <origin
      xyz="0 0.01 0"
      rpy="0 0 0" />
    <parent
      link="Link5" />
    <child
      link="Link6" />
    <axis
      xyz="0 0 1" />
  </joint>
  <link
    name="Link7">
    <inertial>
      <origin
        xyz="0.024087 -0.018375 -0.013114"
        rpy="0 0 0" />
      <mass
        value="1.1659" />
      <inertia
        ixx="0.0056192"
        ixy="-5.5561E-11"
        ixz="1.1617E-05"
        iyy="0.0032147"
        iyz="4.4319E-10"
        izz="0.0030185" />
    </inertial>
    <visual>
      <origin
        xyz="0 0 0"
        rpy="0 0 0" />
      <geometry>
        <mesh
          filename="/home/alec/Autotracking_Surgical_Lamp/ros2_ws/src/surg_bot/surg_bot_description/meshes/Link7.STL" />
      </geometry>
      <material
        name="">
        <color
          rgba="0 0.5 0.5 1" />
      </material>
    </visual>
    <collision>
      <origin
        xyz="0 0 0"
        rpy="0 0 0" />
      <geometry>
        <mesh
          filename="/home/alec/Autotracking_Surgical_Lamp/ros2_ws/src/surg_bot/surg_bot_description/meshes/Link7.STL" />
      </geometry>
    </collision>
  </link>
  <joint
    name="Joint6"
    type="fixed">
    <origin
      xyz="0.34214 -0.028375 -0.41803"
      rpy="0 0 3.1416" />
    <parent
      link="Link6" />
    <child
      link="Link7" />
    <axis
      xyz="0 0 1" />
  </joint>
  <link
    name="Lamp">
    <inertial>
      <origin
        xyz="0.28275 -0.00459 -0.00031991"
        rpy="0 0 0" />
      <mass
        value="44.076" />
      <inertia
        ixx="1.14"
        ixy="0.00042379"
        ixz="1.2264E-05"
        iyy="2.0156"
        iyz="0.00063168"
        izz="1.0565" />
    </inertial>
    <visual>
      <origin
        xyz="0 0 0"
        rpy="0 0 0" />
      <geometry>
        <mesh
          filename="/home/alec/Autotracking_Surgical_Lamp/ros2_ws/src/surg_bot/surg_bot_description/meshes/Lamp.STL" />
      </geometry>
      <material
        name="">
        <color
          rgba="0 0.5 0.5 1" />
      </material>
    </visual>
    <collision>
      <origin
        xyz="0 0 0"
        rpy="0 0 0" />
      <geometry>
        <mesh
          filename="/home/alec/Autotracking_Surgical_Lamp/ros2_ws/src/surg_bot/surg_bot_description/meshes/Lamp.STL" />
      </geometry>
    </collision>
  </link>
  <joint
    name="Joint7"
    type="continuous">
    <origin
      xyz="0.044276 -0.018375 -0.014756"
      rpy="0 0 0" />
    <parent
      link="Link7" />
    <child
      link="Lamp" />
    <axis
      xyz="1 0 0" />
    <limit
      lower="0"
      upper="0"
      effort="0"
      velocity="0" />
  </joint>
</robot>