<sdf version='1.11'>
  <model name='surg_bot_description'>
    <link name='base_link'>
      <inertial>
        <pose>0.106427868445756 0.145639729120602 0.191167836670779 0 0 0</pose>
        <mass>15.865948579378999</mass>
        <inertia>
          <ixx>0.42579179318537502</ixx>
          <ixy>-2.50159888909237e-19</ixy>
          <ixz>8.8094735236897505e-19</ixz>
          <iyy>0.227325591684544</iyy>
          <iyz>-1.0360921171599e-16</iyz>
          <izz>0.42579179318537502</izz>
        </inertia>
      </inertial>
      <collision name='base_link_collision'>
        <pose>0 0 0 0 0 0</pose>
        <geometry>
          <mesh>
            <scale>1 1 1</scale>
            <uri>../meshes/base_link.STL</uri>
          </mesh>
        </geometry>
      </collision>
      <visual name='base_link_visual'>
        <pose>0 0 0 0 0 0</pose>
        <geometry>
          <mesh>
            <scale>1 1 1</scale>
            <uri>../meshes/base_link.STL</uri>
          </mesh>
        </geometry>
        <material>
          <diffuse>0 0.625 0.625 1</diffuse>
          <ambient>0 0.625 0.625 1</ambient>
        </material>
      </visual>
    </link>
    <joint name='Joint0' type='revolute'>
      <pose relative_to='base_link'>0.10643 -0.19117000000000001 0 1.5708 0 0</pose>
      <parent>base_link</parent>
      <child>Link1</child>
      <axis>
        <xyz>0 1 0</xyz>
        <limit>
          <lower>0</lower>
          <upper>0</upper>
          <effort>0</effort>
          <velocity>0</velocity>
        </limit>
        <dynamics>
          <spring_reference>0</spring_reference>
          <spring_stiffness>0</spring_stiffness>
        </dynamics>
      </axis>
    </joint>
    <link name='Link1'>
      <pose relative_to='Joint0'>0 0 0 0 0 0</pose>
      <inertial>
        <pose>0.46817999999999999 -0.054545000000000003 -1.4186000000000001e-06 0 0 0</pose>
        <mass>7.0612000000000004</mass>
        <inertia>
          <ixx>0.11459999999999999</ixx>
          <ixy>0.16994000000000001</ixy>
          <ixz>-7.7718999999999999e-07</ixz>
          <iyy>0.81276999999999999</iyy>
          <iyz>-2.7169000000000002e-07</iyz>
          <izz>0.90344999999999998</izz>
        </inertia>
      </inertial>
      <collision name='Link1_collision'>
        <pose>0 0 0 0 0 0</pose>
        <geometry>
          <mesh>
            <scale>1 1 1</scale>
            <uri>../meshes/Link1.STL</uri>
          </mesh>
        </geometry>
      </collision>
      <visual name='Link1_visual'>
        <pose>0 0 0 0 0 0</pose>
        <geometry>
          <mesh>
            <scale>1 1 1</scale>
            <uri>../meshes/Link1.STL</uri>
          </mesh>
        </geometry>
        <material>
          <diffuse>0 0.625 0.625 1</diffuse>
          <ambient>0 0.625 0.625 1</ambient>
        </material>
      </visual>
    </link>
    <joint name='Joint1' type='revolute'>
      <pose relative_to='Link1'>0.86360000000000003 -0.37436000000000003 0 3.1415926535897931 -1.5707926536359933 3.1415926535897931</pose>
      <parent>Link1</parent>
      <child>Link2</child>
      <axis>
        <xyz>0 1 0</xyz>
        <limit>
          <lower>0</lower>
          <upper>0</upper>
          <effort>0</effort>
          <velocity>0</velocity>
        </limit>
        <dynamics>
          <spring_reference>0</spring_reference>
          <spring_stiffness>0</spring_stiffness>
        </dynamics>
      </axis>
    </joint>
    <link name='Link2'>
      <pose relative_to='Joint1'>0 0 0 0 0 0</pose>
      <inertial>
        <pose>0.00032422000000000001 0.11973 1.1932000000000001e-07 0 0 0</pose>
        <mass>1.1307</mass>
        <inertia>
          <ixx>0.0054576</ixx>
          <ixy>-1.9953e-05</ixy>
          <ixz>3.5927999999999998e-09</ixz>
          <iyy>0.0036384</iyy>
          <iyz>-5.3272000000000004e-09</iyz>
          <izz>0.0045843999999999998</izz>
        </inertia>
      </inertial>
      <collision name='Link2_collision'>
        <pose>0 0 0 0 0 0</pose>
        <geometry>
          <mesh>
            <scale>1 1 1</scale>
            <uri>../meshes/Link2.STL</uri>
          </mesh>
        </geometry>
      </collision>
      <visual name='Link2_visual'>
        <pose>0 0 0 0 0 0</pose>
        <geometry>
          <mesh>
            <scale>1 1 1</scale>
            <uri>../meshes/Link2.STL</uri>
          </mesh>
        </geometry>
        <material>
          <diffuse>0 0.625 0.625 1</diffuse>
          <ambient>0 0.625 0.625 1</ambient>
        </material>
      </visual>
    </link>
    <joint name='Joint2' type='revolute'>
      <pose relative_to='Link2'>-0.050799999999999998 0.127 0 0 0 0</pose>
      <parent>Link2</parent>
      <child>Link3</child>
      <axis>
        <xyz>1 0 0</xyz>
        <limit>
          <lower>-inf</lower>
          <upper>inf</upper>
        </limit>
        <dynamics>
          <spring_reference>0</spring_reference>
          <spring_stiffness>0</spring_stiffness>
        </dynamics>
      </axis>
    </joint>
    <link name='Link3'>
      <pose relative_to='Joint2'>0 0 0 0 0 0</pose>
      <inertial>
        <pose>-0.076096999999999998 1.6976000000000001e-07 -0.0056433999999999998 0 0 0</pose>
        <mass>1.2444</mass>
        <inertia>
          <ixx>0.0057431000000000001</ixx>
          <ixy>-5.3975e-09</ixy>
          <ixz>3.6099000000000001e-05</ixz>
          <iyy>0.0049115000000000001</iyy>
          <iyz>-5.8176999999999999e-09</iyz>
          <izz>0.0039657</izz>
        </inertia>
      </inertial>
      <collision name='Link3_collision'>
        <pose>0 0 0 0 0 0</pose>
        <geometry>
          <mesh>
            <scale>1 1 1</scale>
            <uri>../meshes/Link3.STL</uri>
          </mesh>
        </geometry>
      </collision>
      <visual name='Link3_visual'>
        <pose>0 0 0 0 0 0</pose>
        <geometry>
          <mesh>
            <scale>1 1 1</scale>
            <uri>../meshes/Link3.STL</uri>
          </mesh>
        </geometry>
        <material>
          <diffuse>0 0.625 0.625 1</diffuse>
          <ambient>0 0.625 0.625 1</ambient>
        </material>
      </visual>
    </link>
    <joint name='Joint3' type='revolute'>
      <pose relative_to='Link3'>-0.076200000000000004 0 -0.050799999999999998 0 0 -3.1415853071795872</pose>
      <parent>Link3</parent>
      <child>Link4</child>
      <axis>
        <xyz>0 0 1</xyz>
        <limit>
          <lower>-inf</lower>
          <upper>inf</upper>
        </limit>
        <dynamics>
          <spring_reference>0</spring_reference>
          <spring_stiffness>0</spring_stiffness>
        </dynamics>
      </axis>
    </joint>
    <link name='Link4'>
      <pose relative_to='Joint3'>0 0 0 0 0 0</pose>
      <inertial>
        <pose>-8.0630000000000003e-15 -1.1102e-16 -0.4572 0 0 0</pose>
        <mass>4.0975999999999999</mass>
        <inertia>
          <ixx>0.24440999999999999</ixx>
          <ixy>-3.6765000000000002e-35</ixy>
          <ixz>-8.2378000000000005e-16</ixz>
          <iyy>0.24440999999999999</iyy>
          <iyz>-1.9484e-34</iyz>
          <izz>0.0072065000000000002</izz>
        </inertia>
      </inertial>
      <collision name='Link4_collision'>
        <pose>0 0 0 0 0 0</pose>
        <geometry>
          <mesh>
            <scale>1 1 1</scale>
            <uri>../meshes/Link4.STL</uri>
          </mesh>
        </geometry>
      </collision>
      <visual name='Link4_visual'>
        <pose>0 0 0 0 0 0</pose>
        <geometry>
          <mesh>
            <scale>1 1 1</scale>
            <uri>../meshes/Link4.STL</uri>
          </mesh>
        </geometry>
        <material>
          <diffuse>0 0.625 0.625 1</diffuse>
          <ambient>0 0.625 0.625 1</ambient>
        </material>
      </visual>
    </link>
    <joint name='Joint4' type='revolute'>
      <pose relative_to='Link4'>0 0 -0.83819999999999995 0 0 -3.1415853071795872</pose>
      <parent>Link4</parent>
      <child>Link5</child>
      <axis>
        <xyz>0 0 1</xyz>
        <limit>
          <lower>0</lower>
          <upper>0</upper>
          <effort>0</effort>
          <velocity>0</velocity>
        </limit>
        <dynamics>
          <spring_reference>0</spring_reference>
          <spring_stiffness>0</spring_stiffness>
        </dynamics>
      </axis>
    </joint>
    <link name='Link5'>
      <pose relative_to='Joint4'>0 0 0 0 0 0</pose>
      <inertial>
        <pose>0.0040654999999999997 -1.6223000000000001e-09 -0.048286999999999997 0 0 0</pose>
        <mass>0.28317999999999999</mass>
        <inertia>
          <ixx>0.00044292000000000002</ixx>
          <ixy>3.2676000000000002e-11</ixy>
          <ixz>2.2201e-05</ixz>
          <iyy>0.00050783000000000002</iyy>
          <iyz>1.6452999999999999e-11</iyz>
          <izz>0.00056888999999999996</izz>
        </inertia>
      </inertial>
      <collision name='Link5_collision'>
        <pose>0 0 0 0 0 0</pose>
        <geometry>
          <mesh>
            <scale>1 1 1</scale>
            <uri>../meshes/Link5.STL</uri>
          </mesh>
        </geometry>
      </collision>
      <visual name='Link5_visual'>
        <pose>0 0 0 0 0 0</pose>
        <geometry>
          <mesh>
            <scale>1 1 1</scale>
            <uri>../meshes/Link5.STL</uri>
          </mesh>
        </geometry>
        <material>
          <diffuse>0 0.625 0.625 1</diffuse>
          <ambient>0 0.625 0.625 1</ambient>
        </material>
      </visual>
    </link>
    <joint name='Joint5' type='revolute'>
      <pose relative_to='Link5'>0 0.01 0 0 0 0</pose>
      <parent>Link5</parent>
      <child>Link6</child>
      <axis>
        <xyz>0 0 1</xyz>
        <limit>
          <lower>-inf</lower>
          <upper>inf</upper>
        </limit>
        <dynamics>
          <spring_reference>0</spring_reference>
          <spring_stiffness>0</spring_stiffness>
        </dynamics>
      </axis>
    </joint>
    <link name='Link6'>
      <pose relative_to='Joint5'>0 0 0 0 0 0</pose>
      <inertial>
        <pose>0.23139000000000001 -0.01 -0.15837000000000001 0 0 0</pose>
        <mass>0.46788000000000002</mass>
        <inertia>
          <ixx>0.0030956999999999998</ixx>
          <ixy>-4.6540999999999998e-19</ixy>
          <ixz>0.0027323</ixz>
          <iyy>0.0061092000000000004</iyy>
          <iyz>6.7690000000000003e-19</iyz>
          <izz>0.0030956999999999998</izz>
        </inertia>
      </inertial>
      <collision name='Link6_collision'>
        <pose>0 0 0 0 0 0</pose>
        <geometry>
          <mesh>
            <scale>1 1 1</scale>
            <uri>../meshes/Link6.STL</uri>
          </mesh>
        </geometry>
      </collision>
      <visual name='Link6_visual'>
        <pose>0 0 0 0 0 0</pose>
        <geometry>
          <mesh>
            <scale>1 1 1</scale>
            <uri>../meshes/Link6.STL</uri>
          </mesh>
        </geometry>
        <material>
          <diffuse>0 0.625 0.625 1</diffuse>
          <ambient>0 0.625 0.625 1</ambient>
        </material>
      </visual>
    </link>
    <joint name='Joint6' type='revolute'>
      <pose relative_to='Link6'>0.34214 -0.028375000000000001 -0.41803000000000001 0 0 -3.1415853071795872</pose>
      <parent>Link6</parent>
      <child>Link7</child>
      <axis>
        <xyz>0 0 1</xyz>
        <limit>
          <lower>-inf</lower>
          <upper>inf</upper>
        </limit>
        <dynamics>
          <spring_reference>0</spring_reference>
          <spring_stiffness>0</spring_stiffness>
        </dynamics>
      </axis>
    </joint>
    <link name='Link7'>
      <pose relative_to='Joint6'>0 0 0 0 0 0</pose>
      <inertial>
        <pose>0.024087000000000001 -0.018374999999999999 -0.013114000000000001 0 0 0</pose>
        <mass>1.1658999999999999</mass>
        <inertia>
          <ixx>0.0056192000000000004</ixx>
          <ixy>-5.5561000000000002e-11</ixy>
          <ixz>1.1617000000000001e-05</ixz>
          <iyy>0.0032147</iyy>
          <iyz>4.4319e-10</iyz>
          <izz>0.0030184999999999999</izz>
        </inertia>
      </inertial>
      <collision name='Link7_collision'>
        <pose>0 0 0 0 0 0</pose>
        <geometry>
          <mesh>
            <scale>1 1 1</scale>
            <uri>../meshes/Link7.STL</uri>
          </mesh>
        </geometry>
      </collision>
      <visual name='Link7_visual'>
        <pose>0 0 0 0 0 0</pose>
        <geometry>
          <mesh>
            <scale>1 1 1</scale>
            <uri>../meshes/Link7.STL</uri>
          </mesh>
        </geometry>
        <material>
          <diffuse>0 0.625 0.625 1</diffuse>
          <ambient>0 0.625 0.625 1</ambient>
        </material>
      </visual>
    </link>
    <joint name='Joint7' type='revolute'>
      <pose relative_to='Link7'>0.044276000000000003 -0.018374999999999999 -0.014756 0 0 0</pose>
      <parent>Link7</parent>
      <child>Lamp</child>
      <axis>
        <xyz>1 0 0</xyz>
        <limit>
          <lower>0</lower>
          <upper>0</upper>
          <effort>0</effort>
          <velocity>0</velocity>
        </limit>
        <dynamics>
          <spring_reference>0</spring_reference>
          <spring_stiffness>0</spring_stiffness>
        </dynamics>
      </axis>
    </joint>
    <link name='Lamp'>
      <pose relative_to='Joint7'>0 0 0 0 0 0</pose>
      <inertial>
        <pose>0.28275 -0.0045900000000000003 -0.00031991000000000002 0 0 0</pose>
        <mass>44.076000000000001</mass>
        <inertia>
          <ixx>1.1399999999999999</ixx>
          <ixy>0.00042379000000000001</ixy>
          <ixz>1.2264e-05</ixz>
          <iyy>2.0156000000000001</iyy>
          <iyz>0.00063168000000000002</iyz>
          <izz>1.0565</izz>
        </inertia>
      </inertial>
      <collision name='Lamp_collision'>
        <pose>0 0 0 0 0 0</pose>
        <geometry>
          <mesh>
            <scale>1 1 1</scale>
            <uri>../meshes/Lamp.STL</uri>
          </mesh>
        </geometry>
      </collision>
      <visual name='Lamp_visual'>
        <pose>0 0 0 0 0 0</pose>
        <geometry>
          <mesh>
            <scale>1 1 1</scale>
            <uri>../meshes/Lamp.STL</uri>
          </mesh>
        </geometry>
        <material>
          <diffuse>0 0.625 0.625 1</diffuse>
          <ambient>0 0.625 0.625 1</ambient>
        </material>
      </visual>
    </link>
  </model>
</sdf>
